<?xml version="1.0" encoding="UTF-8"?>
<!-- Generated by org.testng.reporters.JUnitReportReporter -->
<testsuite hostname="liusf-PC" name="testcases.login_normal.Testcase1001_Login_Success_With_Sales_And_Agent" tests="1" failures="1" timestamp="12 Apr 2018 03:54:51 GMT" time="14.017" errors="0">
  <testcase name="test_sales_and_agent_login_by_csv" time="14.017" classname="testcases.login_normal.Testcase1001_Login_Success_With_Sales_And_Agent">
    <failure type="java.lang.AssertionError" message="登录成功后页面跳转错误 expected [http://tujunsat.jimicloud.com/customer/toAccountCenter] but found [http://tujunsat.jimicloud.com/index.jsp;JSESSIONID=23422651-2da1-41a0-b501-556de5d80ed4]">
      <![CDATA[java.lang.AssertionError: 登录成功后页面跳转错误 expected [http://tujunsat.jimicloud.com/customer/toAccountCenter] but found [http://tujunsat.jimicloud.com/index.jsp;JSESSIONID=23422651-2da1-41a0-b501-556de5d80ed4]
	at org.testng.Assert.fail(Assert.java:94)
	at org.testng.Assert.failNotEquals(Assert.java:496)
	at org.testng.Assert.assertEquals(Assert.java:125)
	at org.testng.Assert.assertEquals(Assert.java:178)
	at testcases.login_normal.Testcase1001_Login_Success_With_Sales_And_Agent.test_sales_and_agent_login_by_csv(Testcase1001_Login_Success_With_Sales_And_Agent.java:91)
	at sun.reflect.NativeMethodAccessorImpl.invoke0(Native Method)
	at sun.reflect.NativeMethodAccessorImpl.invoke(Unknown Source)
	at sun.reflect.DelegatingMethodAccessorImpl.invoke(Unknown Source)
	at java.lang.reflect.Method.invoke(Unknown Source)
	at org.testng.internal.MethodInvocationHelper.invokeMethod(MethodInvocationHelper.java:85)
	at org.testng.internal.Invoker.invokeMethod(Invoker.java:639)
	at org.testng.internal.Invoker.invokeTestMethod(Invoker.java:816)
	at org.testng.internal.Invoker.invokeTestMethods(Invoker.java:1124)
	at org.testng.internal.TestMethodWorker.invokeTestMethods(TestMethodWorker.java:125)
	at org.testng.internal.TestMethodWorker.run(TestMethodWorker.java:108)
	at org.testng.TestRunner.privateRun(TestRunner.java:774)
	at org.testng.TestRunner.run(TestRunner.java:624)
	at org.testng.SuiteRunner.runTest(SuiteRunner.java:359)
	at org.testng.SuiteRunner.runSequentially(SuiteRunner.java:354)
	at org.testng.SuiteRunner.privateRun(SuiteRunner.java:312)
	at org.testng.SuiteRunner.run(SuiteRunner.java:261)
	at org.testng.SuiteRunnerWorker.runSuite(SuiteRunnerWorker.java:52)
	at org.testng.SuiteRunnerWorker.run(SuiteRunnerWorker.java:86)
	at org.testng.TestNG.runSuitesSequentially(TestNG.java:1215)
	at org.testng.TestNG.runSuitesLocally(TestNG.java:1140)
	at org.testng.TestNG.run(TestNG.java:1048)
	at org.testng.remote.AbstractRemoteTestNG.run(AbstractRemoteTestNG.java:114)
	at org.testng.remote.RemoteTestNG.initAndRun(RemoteTestNG.java:251)
	at org.testng.remote.RemoteTestNG.main(RemoteTestNG.java:77)
]]>
    </failure>
  </testcase> <!-- test_sales_and_agent_login_by_csv -->
</testsuite> <!-- testcases.login_normal.Testcase1001_Login_Success_With_Sales_And_Agent -->
